2018-11-21 10:17:28,229 - __main__ - INFO - Some random info message from main.py
2018-11-21 10:17:28,229 - __main__ - ERROR - Failed to open file
Traceback (most recent call last):
  File ".\main.py", line 23, in <module>
    open('/path/to/does/not/exist', 'rb')
FileNotFoundError: [Errno 2] No such file or directory: '/path/to/does/not/exist'
2018-11-21 10:40:52,206 - __main__ - INFO - Some random info message from main.py
2018-11-21 10:40:52,206 - __main__ - ERROR - Failed to open file
Traceback (most recent call last):
  File ".\main.py", line 23, in <module>
    open('/path/to/does/not/exist', 'rb')
FileNotFoundError: [Errno 2] No such file or directory: '/path/to/does/not/exist'
2018-11-21 10:41:18,692 - __main__ - INFO - Some random info message from main.py
2018-11-21 10:41:18,695 - __main__ - ERROR - Failed to open file
Traceback (most recent call last):
  File ".\main.py", line 23, in <module>
    open('/path/to/does/not/exist', 'rb')
FileNotFoundError: [Errno 2] No such file or directory: '/path/to/does/not/exist'
2018-11-21 10:41:23,598 - __main__ - INFO - Some random info message from main.py
2018-11-21 10:41:23,598 - __main__ - ERROR - Failed to open file
Traceback (most recent call last):
  File ".\main.py", line 23, in <module>
    open('/path/to/does/not/exist', 'rb')
FileNotFoundError: [Errno 2] No such file or directory: '/path/to/does/not/exist'
